<?xml version="1.0" ?>
<!-- =================================================================================== -->
<!-- |    This document was autogenerated by xacro from /home//minimal_ws/src/five_dof/xacro/five_dof.xacro | -->
<!-- |    EDITING THIS FILE BY HAND IS NOT RECOMMENDED                                 | -->
<!-- =================================================================================== -->
<robot name="five_dof_arm">
    <link name="base_link" />
    <joint name="joint1" type="prismatic">
        <parent link="base_link" />
        <child link="link1" />
        <axis xyz="0 0 -1" />
        <limit effort="10000.0" lower="-0.38" upper="0.38" velocity="0.18" />
        <origin rpy="1.5707963267948966 1.5707963267948966 0" xyz="0.0 0.0 0.988" />
    </joint>
    <link name="link1">
        <visual>
            <geometry>
                <box size="0.0645 0.1054 0.1146" />
            </geometry>
            <origin rpy="0 0 0" xyz="0 0 0" />
        </visual>
        <!-- Collision objectcs of joint <link1> -->
        <collision name="top_center">
            <geometry>
                <box size="0.0645 0.1054 0.1146" />
            </geometry>
            <origin rpy="0 0 0" xyz=" -0.1927 0.001 -0.0009 " />
        </collision>
        <inertial>
            <mass value="8.8719901e+00" />
            <origin rpy="0 0 0" xyz="-1.8378585e-02   -3.3821352e-02   1.5096053e-02" />
            <inertia ixx="1.4628568e+00" ixy="-8.2317164e-03" ixz="-3.7087464e-03" iyy="4.1021036e-02" iyz="-2.6089186e-02" izz="1.4443968e+00" />
        </inertial>
    </link>
    <joint name="joint2" type="revolute">
        <parent link="link1" />
        <child link="link2" />
        <axis xyz="0 0 1" />
        <limit effort="10000.0" lower="-1.5707963267948966" upper="1.5707963267948966" velocity="0.95" />
        <origin rpy="0.0 0.0 0.0" xyz="0.057 0.0 0.0" />
    </joint>
    <link name="link2">
        <visual>
            <geometry>
                <box size="0.2837 0.0991 0.056" />
            </geometry>
            <origin rpy="0 0 0" xyz=" 0.1348 0 0.0362 " />
        </visual>
        <visual>
            <geometry>
                <box size="0.1697 0.0991 0.0422" />
            </geometry>
            <origin rpy="0 0 0" xyz=" 0.1679 0 0.085 " />
        </visual>
        <visual>
            <geometry>
                <cylinder length="0.0573" radius="0.045" />
            </geometry>
            <origin rpy="0 0 0" xyz=" 0 0 0.0364 " />
        </visual>
        <visual>
            <geometry>
                <cylinder length="0.1102" radius="0.0575" />
            </geometry>
            <origin rpy="0 0 0" xyz=" 0.2501 0 0.0498 " />
        </visual>
        <!-- Collision objectcs of joint <link2> -->
        <collision name="main_arm">
            <geometry>
                <box size="0.2837 0.0991 0.056" />
            </geometry>
            <origin rpy="0 0 0" xyz=" 0.1348 0 0.0362 " />
        </collision>
        <collision name="main_arm2">
            <geometry>
                <box size="0.1697 0.0991 0.0422" />
            </geometry>
            <origin rpy="0 0 0" xyz=" 0.1679 0 0.085 " />
        </collision>
        <collision name="cylinder_top">
            <geometry>
                <cylinder length="0.0573" radius="0.045" />
            </geometry>
            <origin rpy="0 0 0" xyz=" 0 0 0.0364 " />
        </collision>
        <collision name="cylinder_bottom">
            <geometry>
                <cylinder length="0.1102" radius="0.0575" />
            </geometry>
            <origin rpy="0 0 0" xyz=" 0.2501 0 0.0498 " />
        </collision>
        <inertial>
            <mass value="6.1827318e+00" />
            <origin rpy="0 0 0" xyz="8.1257835e-03 -2.2423102e-03 -3.8770874e-02" />
            <inertia ixx="4.6295360e-02" ixy="-1.7023486e-03" ixz="2.1592914e-02" iyy="7.6155200e-02" iyz="1.6449264e-04" izz="5.4657100e-02" />
        </inertial>
    </link>
    <joint name="joint3" type="revolute">
        <parent link="link2" />
        <child link="link3" />
        <limit effort="10000.0" lower="-2.443460952792061" upper="2.443460952792061" velocity="0.95" />
        <axis xyz="0 0 1" />
        <origin rpy="3.141592653589793 0 0" xyz="0.250 0.0 -0.0005" />
    </joint>
    <link name="link3">
        <visual>
            <geometry>
                <box size="0.0137 0.05 0.144" />
            </geometry>
            <origin rpy="0 0 -5.3" xyz=" 0.1149 -0.0138 -0.047 " />
        </visual>
        <visual>
            <geometry>
                <box size="0.0137 0.05 0.144" />
            </geometry>
            <origin rpy="0 0 -0.985" xyz=" 0.1142 0.0124 -0.047 " />
        </visual>
        <visual>
            <geometry>
                <box size="0.0137 0.0408 0.0135" />
            </geometry>
            <origin rpy="0 0 -0.785" xyz=" 0.145 -0.0118 -0.0714 " />
        </visual>
        <visual>
            <geometry>
                <box size="0.0137 0.0408 0.0135" />
            </geometry>
            <origin rpy="0 0 -5.498" xyz=" 0.1447 0.0121 -0.0714 " />
        </visual>
        <visual>
            <geometry>
                <box size="0.33 0.0773 0.021" />
            </geometry>
            <origin rpy="0 0 0" xyz=" 0.1179 0.001 -0.1304 " />
        </visual>
        <visual>
            <geometry>
                <box size="0.33 0.0773 0.0597" />
            </geometry>
            <origin rpy="0 0 0" xyz=" 0.1078 0.001 0.04 " />
        </visual>
        <visual>
            <geometry>
                <box size="0.1444 0.0773 0.0331" />
            </geometry>
            <origin rpy="0 0 0" xyz=" 0.2124 0.001 -0.0057 " />
        </visual>
        <!-- Collision objectcs of joint <link3> -->
        <collision name="slope_back1">
            <geometry>
                <box size="0.0137 0.05 0.144" />
            </geometry>
            <origin rpy="0 0 -5.3" xyz=" 0.1149 -0.0138 -0.047 " />
        </collision>
        <collision name="slope_back2">
            <geometry>
                <box size="0.0137 0.05 0.144" />
            </geometry>
            <origin rpy="0 0 -0.985" xyz=" 0.1142 0.0124 -0.047 " />
        </collision>
        <collision name="slope_inner1">
            <geometry>
                <box size="0.0137 0.0408 0.0135" />
            </geometry>
            <origin rpy="0 0 -0.785" xyz=" 0.145 -0.0118 -0.0714 " />
        </collision>
        <collision name="slope_inner2">
            <geometry>
                <box size="0.0137 0.0408 0.0135" />
            </geometry>
            <origin rpy="0 0 -5.498" xyz=" 0.1447 0.0121 -0.0714 " />
        </collision>
        <collision name="side_left">
            <geometry>
                <box size="0.33 0.0773 0.021" />
            </geometry>
            <origin rpy="0 0 0" xyz=" 0.1179 0.001 -0.1304 " />
        </collision>
        <collision name="side_right">
            <geometry>
                <box size="0.33 0.0773 0.0597" />
            </geometry>
            <origin rpy="0 0 0" xyz=" 0.1078 0.001 0.04 " />
        </collision>
        <collision name="side_right2">
            <geometry>
                <box size="0.1444 0.0773 0.0331" />
            </geometry>
            <origin rpy="0 0 0" xyz=" 0.2124 0.001 -0.0057 " />
        </collision>
        <inertial>
            <mass value="1.4598751e+00" />
            <origin rpy="0 0 0" xyz="1.3269219e-01 3.4762815e-04 1.7908358e-02" />
            <inertia ixx="2.5612714e-03" ixy="-7.5697321e-05" ixz="-3.0403357e-03" iyy="3.3672576e-02" iyz="-9.2591653e-06" izz="3.3319691e-02" />
        </inertial>
    </link>
    <joint name="joint4" type="revolute">
        <parent link="link3" />
        <child link="link4" />
        <limit effort="10000.0" lower="-2.234021442552742" upper="2.234021442552742" velocity="2" />
        <axis xyz="0 0 1" />
        <origin rpy="3.141592653589793 0 0" xyz="0.250 0 -0.018" />
    </joint>
    <link name="link4">
        <visual>
            <geometry>
                <cylinder length="0.0766" radius="0.05" />
            </geometry>
            <origin rpy="0 0 0" xyz=" -0.0136 0.0028 0.0529 " />
        </visual>
        <visual>
            <geometry>
                <sphere radius="0.049" />
            </geometry>
            <origin rpy="0 0 0" xyz=" -0.0123 -0.005 0.0518 " />
        </visual>
        <visual>
            <geometry>
                <sphere radius="0.049" />
            </geometry>
            <origin rpy="0 0 0" xyz=" -0.0123 0.0058 0.0518 " />
        </visual>
        <!-- Collision objectcs of joint <link4> -->
        <collision name="main_engine_top">
            <geometry>
                <cylinder length="0.0766" radius="0.05" />
            </geometry>
            <origin rpy="0 0 0" xyz=" -0.0136 0.0028 0.0529 " />
        </collision>
        <collision name="sphere1">
            <geometry>
                <sphere radius="0.049" />
            </geometry>
            <origin rpy="0 0 0" xyz=" -0.0123 -0.005 0.0518 " />
        </collision>
        <collision name="sphere2">
            <geometry>
                <sphere radius="0.049" />
            </geometry>
            <origin rpy="0 0 0" xyz=" -0.0123 0.0058 0.0518 " />
        </collision>
        <inertial>
            <mass value="1.2261021e+00" />
            <origin rpy="0 0 0" xyz="-1.7663553e-02 -2.1400688e-06 6.7029970e-02" />
            <inertia ixx="7.7772921e-03" ixy="5.0719985e-06" ixz="1.6625761e-03" iyy="8.2624081e-03" iyz="-1.1703353e-05" izz="2.3620978e-03" />
        </inertial>
    </link>
    <joint name="joint5" type="revolute">
        <parent link="link4" />
        <child link="link5" />
        <limit effort="10000.0" lower="-1.5707963267948966" upper="1.5707963267948966" velocity="2" />
        <axis xyz="0 0 1" />
        <origin rpy="1.5707963267948966 0 1.5707963267948966" xyz="0.028 0.0 0.0535" />
    </joint>
    <link name="link5">
        <visual>
            <geometry>
                <box size="0.0351 0.0896 0.066" />
            </geometry>
            <origin rpy="0 0 0" xyz="0 0 0" />
        </visual>
        <visual>
            <geometry>
                <box size="0.0351 0.0896 0.066" />
            </geometry>
            <origin rpy="0 0 0" xyz=" -0.0365 0.001 0.0587 " />
        </visual>
        <visual>
            <geometry>
                <box size="0.0422 0.0519 0.0376" />
            </geometry>
            <origin rpy="0 0 0" xyz=" -0.0702 -0.0096 0.0552 " />
        </visual>
        <visual>
            <geometry>
                <box size="0.0636 0.0026 0.0041" />
            </geometry>
            <origin rpy="0 0 -0.091" xyz=" -0.1295 -0.009 0.0529 " />
        </visual>
        <visual>
            <geometry>
                <box size="0.0636 0.0029 0.0034" />
            </geometry>
            <origin rpy="0 0 -6.171" xyz=" -0.1293 -0.0254 0.0523 " />
        </visual>
        <visual>
            <geometry>
                <cylinder length="0.0754" radius="0.0451" />
            </geometry>
            <origin rpy="0 0 0" xyz=" 0 0 0.0462 " />
        </visual>
        <visual>
            <geometry>
                <sphere radius="0.0462" />
            </geometry>
            <origin rpy="0 0 0" xyz=" 0.0093 0 0.0626 " />
        </visual>
        <!-- Collision objectcs of joint <link5> -->
        <collision name="box1">
            <geometry>
                <box size="0.0351 0.0896 0.066" />
            </geometry>
            <origin rpy="0 0 0" xyz=" -0.0365 0.001 0.0587 " />
        </collision>
        <collision name="box2">
            <geometry>
                <box size="0.0422 0.0519 0.0376" />
            </geometry>
            <origin rpy="0 0 0" xyz=" -0.0702 -0.0096 0.0552 " />
        </collision>
        <collision name="gripper_left">
            <geometry>
                <box size="0.0636 0.0026 0.0041" />
            </geometry>
            <origin rpy="0 0 -0.091" xyz=" -0.1295 -0.009 0.0529 " />
        </collision>
        <collision name="scissor_left">
            <geometry>
                <box size="0.0636 0.0029 0.0034" />
            </geometry>
            <origin rpy="0 0 -6.171" xyz=" -0.1293 -0.0254 0.0523 " />
        </collision>
        <collision name="main_cylinder">
            <geometry>
                <cylinder length="0.0754" radius="0.0451" />
            </geometry>
            <origin rpy="0 0 0" xyz=" 0 0 0.0462 " />
        </collision>
        <collision name="sphere">
            <geometry>
                <sphere radius="0.0462" />
            </geometry>
            <origin rpy="0 0 0" xyz=" 0.0093 0 0.0626 " />
        </collision>
        <inertial>
            <mass value="8.1120008e-01" />
            <origin rpy="0 0 0" xyz="8.1884004e-02 -1.3296172e-02 4.5105514e-02" />
            <inertia ixx="2.8470601e-03" ixy="1.2951004e-03" ixz="-3.1199988e-03" iyy="1.0920152e-02" iyz="5.0823687e-04" izz="9.7649640e-03" />
        </inertial>
    </link>
    <joint name="link5_to_EE" type="fixed">
        <parent link="link5" />
        <child link="EE" />
        <origin rpy="0 0.0 3.141592653589793" xyz="-0.160 -0.0175 0.054" />
    </joint>
    <link name="EE" />
    <transmission name="trans_joint1">
        <type>transmission_interface/SimpleTransmission</type>
        <joint name="joint1">
            <hardwareInterface>hardware_interface/PositionJointInterface</hardwareInterface>
        </joint>
        <actuator name="joint1_motor">
            <hardwareInterface>hardware_interface/PositionJointInterface</hardwareInterface>
            <mechanicalReduction>1</mechanicalReduction>
        </actuator>
    </transmission>
    <transmission name="trans_joint2">
        <type>transmission_interface/SimpleTransmission</type>
        <joint name="joint2">
            <hardwareInterface>hardware_interface/PositionJointInterface</hardwareInterface>
        </joint>
        <actuator name="joint2_motor">
            <hardwareInterface>hardware_interface/PositionJointInterface</hardwareInterface>
            <mechanicalReduction>1</mechanicalReduction>
        </actuator>
    </transmission>
    <transmission name="trans_joint3">
        <type>transmission_interface/SimpleTransmission</type>
        <joint name="joint3">
            <hardwareInterface>hardware_interface/PositionJointInterface</hardwareInterface>
        </joint>
        <actuator name="joint3_motor">
            <hardwareInterface>hardware_interface/PositionJointInterface</hardwareInterface>
            <mechanicalReduction>1</mechanicalReduction>
        </actuator>
    </transmission>
    <transmission name="trans_joint4">
        <type>transmission_interface/SimpleTransmission</type>
        <joint name="joint4">
            <hardwareInterface>hardware_interface/PositionJointInterface</hardwareInterface>
        </joint>
        <actuator name="joint4_motor">
            <hardwareInterface>hardware_interface/PositionJointInterface</hardwareInterface>
            <mechanicalReduction>1</mechanicalReduction>
        </actuator>
    </transmission>
    <transmission name="trans_joint5">
        <type>transmission_interface/SimpleTransmission</type>
        <joint name="joint5">
            <hardwareInterface>hardware_interface/PositionJointInterface</hardwareInterface>
        </joint>
        <actuator name="joint5_motor">
            <hardwareInterface>hardware_interface/PositionJointInterface</hardwareInterface>
            <mechanicalReduction>1</mechanicalReduction>
        </actuator>
    </transmission>
    <gazebo>
        <plugin name="gazebo_ros_control">
            <robotNamespace>/</robotNamespace>
        </plugin>
    </gazebo>
</robot>

